Workbook

Sheet Summary
A1: Budget Analysis Summary
A2: Source: data/example (4 categorized file(s))
A5: Overall Summary
E6: Flow | F6: income | G6: refund (credit) | H6: expenses | I6: refund (debit)
A7: Transaction Category | B7: Credit (CHF) | C7: Debit (CHF) | E7: Income | F7: 23500 | G7: 2394.75 | H7: 0 | I7: 0
A8: Income | B8: 23500 | C8: 0 | E8: Expenses | F8: 0 | G8: 0 | H8: 9674.96 | I8: 0
A9: Expense | B9: 0 | C9: 9674.96
A10: Refund | B10: 2394.75 | C10: 0
A11: Total | B11: 25894.75 | C11: 9674.96
A13: Transfer | B13: 450 | C13: 800
A15: Grand Total | B15: 26344.75 | C15: 10474.96
A17: Check (Transactions) | B17: =SUMIFS(Transactions!$J$2:$J$104, Transactions!$D$2:$D$104, "Income") + SUMIFS(Transactions!$J$2:$J$104, Transactions!$D$2:$D$104, "Expense") + SUMIFS(Transactions!$J$2:$J$104, Transactions!$D$2:$D$104, "Refund") + SUMIFS(Transactions!$J$2:$J$104, Transactions!$D$2:$D$104, "Transfer") | C17: =SUMIFS(Transactions!$K$2:$K$104, Transactions!$D$2:$D$104, "Income") + SUMIFS(Transactions!$K$2:$K$104, Transactions!$D$2:$D$104, "Expense") + SUMIFS(Transactions!$K$2:$K$104, Transactions!$D$2:$D$104, "Refund") + SUMIFS(Transactions!$K$2:$K$104, Transactions!$D$2:$D$104, "Transfer")
A18: Difference | B18: =B17-B15 | C18: =C17-C15

Sheet Overviews by category
A1: Budget Analysis by Category
A2: Source: data/example (4 categorized file(s))
A5: Income by Category
A7: Category | B7: Amount (CHF)
A8: Einkommen | B8: 23500
A9: Total | B9: 23500
A10: Check (Transactions) | B10: =SUMIFS(Transactions!$J$2:$J$104, Transactions!$D$2:$D$104, "Income") - SUMIFS(Transactions!$K$2:$K$104, Transactions!$D$2:$D$104, "Income")
A11: Difference | B11: =B10-B9
A27: Expenses by Category
A29: Category | B29: Amount (CHF)
A30: Wohnen | B30: 7265.12
A31: Einkaufen | B31: 1482.19
A32: Leben | B32: 437.55
A33: Freizeit | B33: 193
A34: Finanzen | B34: 173.5
A35: Mobilität | B35: 123.6
A36: Total | B36: 9674.96
A37: Check (Transactions) | B37: =SUMIFS(Transactions!$K$2:$K$104, Transactions!$D$2:$D$104, "Expense") - SUMIFS(Transactions!$J$2:$J$104, Transactions!$D$2:$D$104, "Expense")
A38: Difference | B38: =B37-B36
A49: Refunds by Category
A51: Category | B51: Amount (CHF)
A52: Leben | B52: 1922.95
A53: Freizeit | B53: 280
A54: Mobilität | B54: 190.8
A55: Rückerstattungen | B55: 1
A56: Total | B56: 2394.75
A57: Check (Transactions) | B57: =SUMIFS(Transactions!$J$2:$J$104, Transactions!$D$2:$D$104, "Refund") - SUMIFS(Transactions!$K$2:$K$104, Transactions!$D$2:$D$104, "Refund")
A58: Difference | B58: =B57-B56

Sheet Category Analysis
A1: Category Analysis
A2: Note: Transactions with Transaction Category 'transfer' are excluded.
A5: January 2025
A7: Category | B7: Credit in CHF | C7: Debit in CHF | D7: Net in CHF
A8: Einkommen | B8: 4200 | C8: 0 | D8: 4200
A9: Wohnen | B9: 0 | C9: 1819.1 | D9: -1819.1
A10: Einkaufen | B10: 0 | C10: 333.05 | D10: -333.05
A11: Mobilität | B11: 0 | C11: 26.7 | D11: -26.7
A12: Freizeit | B12: 0 | C12: 24.5 | D12: -24.5
A13: Leben | B13: 0 | C13: 19 | D13: -19
A14: Rückerstattungen | B14: 1 | C14: 0 | D14: 1
A15: Total | B15: 4201 | C15: 2222.35 | D15: 1978.65
A16: Check (Transactions) | B16: =SUMIFS(Transactions!$J$2:$J$104, Transactions!$C$2:$C$104, "2025-01", Transactions!$D$2:$D$104, "<>Transfer") | C16: =SUMIFS(Transactions!$K$2:$K$104, Transactions!$C$2:$C$104, "2025-01", Transactions!$D$2:$D$104, "<>Transfer") | D16: =SUMIFS(Transactions!$J$2:$J$104, Transactions!$C$2:$C$104, "2025-01", Transactions!$D$2:$D$104, "<>Transfer") - SUMIFS(Transactions!$K$2:$K$104, Transactions!$C$2:$C$104, "2025-01", Transactions!$D$2:$D$104, "<>Transfer")
A17: Difference | B17: =B16-B15 | C17: =C16-C15 | D17: =D16-D15
A20: February 2025
A22: Category | B22: Credit in CHF | C22: Debit in CHF | D22: Net in CHF
A23: Einkommen | B23: 4200 | C23: 0 | D23: 4200
A24: Wohnen | B24: 0 | C24: 1774 | D24: -1774
A25: Einkaufen | B25: 0 | C25: 434.7 | D25: -434.7
A26: Freizeit | B26: 180 | C26: 3 | D26: 177
A27: Mobilität | B27: 48.4 | C27: 0 | D27: 48.4
A28: Total | B28: 4428.4 | C28: 2211.7 | D28: 2216.7
A29: Check (Transactions) | B29: =SUMIFS(Transactions!$J$2:$J$104, Transactions!$C$2:$C$104, "2025-02", Transactions!$D$2:$D$104, "<>Transfer") | C29: =SUMIFS(Transactions!$K$2:$K$104, Transactions!$C$2:$C$104, "2025-02", Transactions!$D$2:$D$104, "<>Transfer") | D29: =SUMIFS(Transactions!$J$2:$J$104, Transactions!$C$2:$C$104, "2025-02", Transactions!$D$2:$D$104, "<>Transfer") - SUMIFS(Transactions!$K$2:$K$104, Transactions!$C$2:$C$104, "2025-02", Transactions!$D$2:$D$104, "<>Transfer")
A30: Difference | B30: =B29-B28 | C30: =C29-C28 | D30: =D29-D28
A33: March 2025
A35: Category | B35: Credit in CHF | C35: Debit in CHF | D35: Net in CHF
A36: Einkommen | B36: 5700 | C36: 0 | D36: 5700
A37: Leben | B37: 1787.95 | C37: 418.55 | D37: 1369.4
A38: Wohnen | B38: 0 | C38: 1898.02 | D38: -1898.02
A39: Einkaufen | B39: 0 | C39: 352.79 | D39: -352.79
A40: Mobilität | B40: 96.9 | C40: 96.9 | D40: 0
A41: Freizeit | B41: 0 | C41: 165.5 | D41: -165.5
A42: Uncategorized | B42: 0 | C42: 12.4 | D42: -12.4
A43: Finanzen | B43: 0 | C43: 5 | D43: -5
A44: Total | B44: 7584.85 | C44: 2949.16 | D44: 4635.69
A45: Check (Transactions) | B45: =SUMIFS(Transactions!$J$2:$J$104, Transactions!$C$2:$C$104, "2025-03", Transactions!$D$2:$D$104, "<>Transfer") | C45: =SUMIFS(Transactions!$K$2:$K$104, Transactions!$C$2:$C$104, "2025-03", Transactions!$D$2:$D$104, "<>Transfer") | D45: =SUMIFS(Transactions!$J$2:$J$104, Transactions!$C$2:$C$104, "2025-03", Transactions!$D$2:$D$104, "<>Transfer") - SUMIFS(Transactions!$K$2:$K$104, Transactions!$C$2:$C$104, "2025-03", Transactions!$D$2:$D$104, "<>Transfer")
A46: Difference | B46: =B45-B44 | C46: =C45-C44 | D46: =D45-D44
A49: April 2025
A51: Category | B51: Credit in CHF | C51: Debit in CHF | D51: Net in CHF
A52: Einkommen | B52: 9400 | C52: 0 | D52: 9400
...

Sheet Subcategory Analysis
A1: Subcategory Analysis
A2: Note: Transactions with Transaction Category 'transfer' are excluded.
A5: January 2025
A7: Category | B7: Subcategory | C7: Credit in CHF | D7: Debit in CHF | E7: Net in CHF
A8: Einkaufen | B8: Supermärkte | C8: 0 | D8: 333.05 | E8: -333.05
A9: Einkommen | B9: Lohn | C9: 4000 | D9: 0 | E9: 4000
A10: Einkommen | B10: Familienzulage | C10: 200 | D10: 0 | E10: 200
A11: Freizeit | B11: Gastronomie | C11: 0 | D11: 24.5 | E11: -24.5
A12: Leben | B12: Familie | C12: 0 | D12: 19 | E12: -19
A13: Mobilität | B13: Privater Verkehr | C13: 0 | D13: 26.7 | E13: -26.7
A14: Wohnen | B14: Miete und Hypothek | C14: 0 | D14: 1774 | E14: -1774
A15: Wohnen | B15: Haushalt | C15: 0 | D15: 45.1 | E15: -45.1
A16: Total | C16: 4200 | D16: 2222.35 | E16: 1977.65
A17: Check (Transactions) | C17: =SUMIFS(Transactions!$J$2:$J$104, Transactions!$C$2:$C$104, "2025-01", Transactions!$D$2:$D$104, "<>Transfer", Transactions!$F$2:$F$104, "<>") | D17: =SUMIFS(Transactions!$K$2:$K$104, Transactions!$C$2:$C$104, "2025-01", Transactions!$D$2:$D$104, "<>Transfer", Transactions!$F$2:$F$104, "<>") | E17: =SUMIFS(Transactions!$J$2:$J$104, Transactions!$C$2:$C$104, "2025-01", Transactions!$D$2:$D$104, "<>Transfer", Transactions!$F$2:$F$104, "<>") - SUMIFS(Transactions!$K$2:$K$104, Transactions!$C$2:$C$104, "2025-01", Transactions!$D$2:$D$104, "<>Transfer", Transactions!$F$2:$F$104, "<>")
A18: Difference | C18: =C17-C16 | D18: =D17-D16 | E18: =E17-E16
A21: February 2025
A23: Category | B23: Subcategory | C23: Credit in CHF | D23: Debit in CHF | E23: Net in CHF
A24: Einkaufen | B24: Supermärkte | C24: 0 | D24: 434.7 | E24: -434.7
A25: Einkommen | B25: Lohn | C25: 4000 | D25: 0 | E25: 4000
A26: Einkommen | B26: Familienzulage | C26: 200 | D26: 0 | E26: 200
A27: Freizeit | B27: Reisen und Erleben | C27: 180 | D27: 0 | E27: 180
A28: Freizeit | B28: Gastronomie | C28: 0 | D28: 3 | E28: -3
A29: Mobilität | B29: Öffentlicher Verkehr | C29: 48.4 | D29: 0 | E29: 48.4
A30: Wohnen | B30: Miete und Hypothek | C30: 0 | D30: 1774 | E30: -1774
A31: Total | C31: 4428.4 | D31: 2211.7 | E31: 2216.7
A32: Check (Transactions) | C32: =SUMIFS(Transactions!$J$2:$J$104, Transactions!$C$2:$C$104, "2025-02", Transactions!$D$2:$D$104, "<>Transfer", Transactions!$F$2:$F$104, "<>") | D32: =SUMIFS(Transactions!$K$2:$K$104, Transactions!$C$2:$C$104, "2025-02", Transactions!$D$2:$D$104, "<>Transfer", Transactions!$F$2:$F$104, "<>") | E32: =SUMIFS(Transactions!$J$2:$J$104, Transactions!$C$2:$C$104, "2025-02", Transactions!$D$2:$D$104, "<>Transfer", Transactions!$F$2:$F$104, "<>") - SUMIFS(Transactions!$K$2:$K$104, Transactions!$C$2:$C$104, "2025-02", Transactions!$D$2:$D$104, "<>Transfer", Transactions!$F$2:$F$104, "<>")
A33: Difference | C33: =C32-C31 | D33: =D32-D31 | E33: =E32-E31
A36: March 2025
A38: Category | B38: Subcategory | C38: Credit in CHF | D38: Debit in CHF | E38: Net in CHF
A39: Einkaufen | B39: Supermärkte | C39: 0 | D39: 170.85 | E39: -170.85
A40: Einkaufen | B40: Detail-Lebensmittel | C40: 0 | D40: 167.29 | E40: -167.29
A41: Einkaufen | B41: Sonstiges Einkaufen | C41: 0 | D41: 14.65 | E41: -14.65
A42: Einkommen | B42: Lohn | C42: 4000 | D42: 0 | E42: 4000
A43: Einkommen | B43: Bonus | C43: 1500 | D43: 0 | E43: 1500
A44: Einkommen | B44: Familienzulage | C44: 200 | D44: 0 | E44: 200
A45: Finanzen | B45: Fees | C45: 0 | D45: 5 | E45: -5
A46: Freizeit | B46: Gastronomie | C46: 0 | D46: 150.5 | E46: -150.5
A47: Freizeit | B47: Kultur | C47: 0 | D47: 15 | E47: -15
A48: Leben | B48: Krankenkasse | C48: 1787.95 | D48: 77.45 | E48: 1710.5
A49: Leben | B49: Familie | C49: 0 | D49: 200 | E49: -200
...

Sheet Transactions
A1: Transaction ID | B1: Date | C1: Month | D1: Transaction Category | E1: Category | F1: Subcategory | G1: Category / Subcategory | H1: Payee | I1: Reference | J1: Credit | K1: Debit | L1: Amount | M1: Rule | N1: Source File
A2: TX-000059 | B2: 45660 | C2: 2025-01 | D2: Expense | E2: Mobilität | F2: Privater Verkehr | G2: Mobilität / Privater Verkehr | H2: MOBILITY MUSTER GENOSSENSCHAFT 6343 ROTKREUZ | I2: MUSTERBANK AG MUSTERSTRASSE 12 6002 LUZERN | J2: 0 | K2: 26.7 | L2: 26.7 | M2: transport_2 | N2: export.202501.categorized.csv
A3: TX-000078 | B3: 45661 | C3: 2025-01 | D3: Expense | E3: Einkaufen | F3: Supermärkte | G3: Einkaufen / Supermärkte | H3: MIGROS M RIVERSIDE (7741) | J3: 0 | K3: 41.2 | L3: 41.2 | M3: supermarket_1 | N3: export.202501.categorized.csv
A4: TX-000077 | B4: 45667 | C4: 2025-01 | D4: Expense | E4: Einkaufen | F4: Supermärkte | G4: Einkaufen / Supermärkte | H4: MIGROS MARKTHALLE (8812) | J4: 0 | K4: 118.3 | L4: 118.3 | M4: supermarket_1 | N4: export.202501.categorized.csv
A5: TX-000057 | B5: 45672 | C5: 2025-01 | D5: Expense | E5: Leben | F5: Familie | G5: Leben / Familie | H5: ZMITTAG 13.1. | I5: ZMITTAG 13.1. | J5: 0 | K5: 19 | L5: 19 | M5: family_2 | N5: export.202501.categorized.csv
A6: TX-000076.1 | B6: 45675 | C6: 2025-01 | D6: Expense | E6: Freizeit | F6: Gastronomie | G6: Freizeit / Gastronomie | H6: COOP-5510 RIVERSIDE REST. | J6: 0 | K6: 24.5 | L6: 24.5 | M6: supermarket_1 | N6: export.202501.categorized.csv
A7: TX-000076.2 | B7: 45675 | C7: 2025-01 | D7: Expense | E7: Wohnen | F7: Haushalt | G7: Wohnen / Haushalt | H7: COOP-5510 RIVERSIDE REST. | J7: 0 | K7: 31.2 | L7: 31.2 | M7: supermarket_1 | N7: export.202501.categorized.csv
A8: TX-000076.3 | B8: 45675 | C8: 2025-01 | D8: Expense | E8: Einkaufen | F8: Supermärkte | G8: Einkaufen / Supermärkte | H8: COOP-5510 RIVERSIDE REST. | J8: 0 | K8: 77.15 | L8: 77.15 | M8: supermarket_1 | N8: export.202501.categorized.csv
A9: TX-000002 | B9: 45676 | C9: 2025-01 | D9: Expense | E9: Wohnen | F9: Haushalt | G9: Wohnen / Haushalt | H9: ONLINE HAUSHALT AG | I9: PAYMENT ID 250119000000000000 BESTELLNUMMER DP-P-00000000 | J9: 0 | K9: 13.9 | L9: 13.9 | M9: home_3 | N9: export.202501.categorized.csv
A10: TX-000001 | B10: 45682 | C10: 2025-01 | D10: Refund | E10: Rückerstattungen | G10: Rückerstattungen | H10: +41790000000 MAX MUSTER | I10: MITTEILUNGEN: TEST | J10: 1 | K10: 0 | L10: -1 | M10: refund_1 | N10: export.202501.categorized.csv
A11: TX-000070.1 | B11: 45682 | C11: 2025-01 | D11: Income | E11: Einkommen | F11: Familienzulage | G11: Einkommen / Familienzulage | H11: ALPENWERK AG INDUSTRIESTRASSE 12 CH-5430 WETTINGEN AG | I11: SALAER JANUAR 2025 | SALA00000000000000000000000000000001 9988776655/1XXXX 250125CH0EXMPL01 | J11: 200 | K11: 0 | L11: -200 | M11: income_1 | N11: export.202501.categorized.csv
A12: TX-000070.2 | B12: 45682 | C12: 2025-01 | D12: Income | E12: Einkommen | F12: Lohn | G12: Einkommen / Lohn | H12: ALPENWERK AG INDUSTRIESTRASSE 12 CH-5430 WETTINGEN AG | I12: SALAER JANUAR 2025 | SALA00000000000000000000000000000001 9988776655/1XXXX 250125CH0EXMPL01 | J12: 4000 | K12: 0 | L12: -4000 | M12: income_1 | N12: export.202501.categorized.csv
A13: TX-000091 | B13: 45683 | C13: 2025-01 | D13: Transfer | E13: Vorsorge | F13: Säule 3a | G13: Vorsorge / Säule 3a | H13: VORSORGESTIFTUNG MUSTERHAUSEN SENDER REFERENZ: SAEULE 3A | I13: 90-11223344 | J13: 0 | K13: 200 | L13: 200 | M13: savings_1 | N13: export.202501.categorized.csv
A14: TX-000075 | B14: 45685 | C14: 2025-01 | D14: Expense | E14: Einkaufen | F14: Supermärkte | G14: Einkaufen / Supermärkte | H14: MIGROS MARKTHALLE (8812) | J14: 0 | K14: 96.4 | L14: 96.4 | M14: supermarket_1 | N14: export.202501.categorized.csv
A15: TX-000074 | B15: 45688 | C15: 2025-01 | D15: Expense | E15: Wohnen | F15: Miete und Hypothek | G15: Wohnen / Miete und Hypothek | H15: FINANZVERWALTUNG STADT SOLOTHURN | I15: 2025/02/01 / 7045128 | J15: 0 | K15: 1774 | L15: 1774 | M15: housing_1 | N15: export.202501.categorized.csv
A16: TX-000083 | B16: 45689 | C16: 2025-02 | D16: Expense | E16: Einkaufen | F16: Supermärkte | G16: Einkaufen / Supermärkte | H16: MIGROS M RIVERSIDE (7741) | J16: 0 | K16: 63.75 | L16: 63.75 | M16: supermarket_1 | N16: export.202502.categorized.csv
A17: TX-000082 | B17: 45696 | C17: 2025-02 | D17: Expense | E17: Einkaufen | F17: Supermärkte | G17: Einkaufen / Supermärkte | H17: MIGROS MARKTHALLE (8812) | J17: 0 | K17: 127.4 | L17: 127.4 | M17: supermarket_1 | N17: export.202502.categorized.csv
A18: TX-000081 | B18: 45702 | C18: 2025-02 | D18: Expense | E18: Einkaufen | F18: Supermärkte | G18: Einkaufen / Supermärkte | H18: COOP-5510 RIVERSIDE REST. | J18: 0 | K18: 88.95 | L18: 88.95 | M18: supermarket_1 | N18: export.202502.categorized.csv
A19: TX-000080 | B19: 45710 | C19: 2025-02 | D19: Expense | E19: Einkaufen | F19: Supermärkte | G19: Einkaufen / Supermärkte | H19: MIGROS MARKTHALLE (8812) | J19: 0 | K19: 154.6 | L19: 154.6 | M19: supermarket_1 | N19: export.202502.categorized.csv
A20: TX-000071.1 | B20: 45713 | C20: 2025-02 | D20: Income | E20: Einkommen | F20: Familienzulage | G20: Einkommen / Familienzulage | H20: ALPENWERK AG INDUSTRIESTRASSE 12 CH-5430 WETTINGEN AG | I20: SALAER FEBRUAR 2025 | SALA00000000000000000000000000000002 9988776655/1XXXX 250225CH0EXMPL02 | J20: 200 | K20: 0 | L20: -200 | M20: income_1 | N20: export.202502.categorized.csv
A21: TX-000071.2 | B21: 45713 | C21: 2025-02 | D21: Income | E21: Einkommen | F21: Lohn | G21: Einkommen / Lohn | H21: ALPENWERK AG INDUSTRIESTRASSE 12 CH-5430 WETTINGEN AG | I21: SALAER FEBRUAR 2025 | SALA00000000000000000000000000000002 9988776655/1XXXX 250225CH0EXMPL02 | J21: 4000 | K21: 0 | L21: -4000 | M21: income_1 | N21: export.202502.categorized.csv
A22: TX-000071.3 | B22: 45713 | C22: 2025-02 | D22: Refund | E22: Freizeit | F22: Reisen und Erleben | G22: Freizeit / Reisen und Erleben | H22: ALPENWERK AG INDUSTRIESTRASSE 12 CH-5430 WETTINGEN AG | I22: SALAER FEBRUAR 2025 | SALA00000000000000000000000000000002 9988776655/1XXXX 250225CH0EXMPL02 | J22: 180 | K22: 0 | L22: -180 | M22: income_1 | N22: export.202502.categorized.csv
A23: TX-000071.4 | B23: 45713 | C23: 2025-02 | D23: Refund | E23: Mobilität | F23: Öffentlicher Verkehr | G23: Mobilität / Öffentlicher Verkehr | H23: ALPENWERK AG INDUSTRIESTRASSE 12 CH-5430 WETTINGEN AG | I23: SALAER FEBRUAR 2025 | SALA00000000000000000000000000000002 9988776655/1XXXX 250225CH0EXMPL02 | J23: 48.4 | K23: 0 | L23: -48.4 | M23: income_1 | N23: export.202502.categorized.csv
A24: TX-000092 | B24: 45714 | C24: 2025-02 | D24: Transfer | E24: Vorsorge | F24: Säule 3a | G24: Vorsorge / Säule 3a | H24: VORSORGESTIFTUNG MUSTERHAUSEN SENDER REFERENZ: SAEULE 3A | I24: 90-11223344 | J24: 0 | K24: 200 | L24: 200 | M24: savings_1 | N24: export.202502.categorized.csv
A25: TX-000060 | B25: 45715 | C25: 2025-02 | D25: Expense | E25: Freizeit | F25: Gastronomie | G25: Freizeit / Gastronomie | H25: MUSTER CAFE | J25: 0 | K25: 3 | L25: 3 | M25: gastronomy_6 | N25: export.202502.categorized.csv
A26: TX-000079 | B26: 45716 | C26: 2025-02 | D26: Expense | E26: Wohnen | F26: Miete und Hypothek | G26: Wohnen / Miete und Hypothek | H26: FINANZVERWALTUNG STADT SOLOTHURN | I26: 2025/03/01 / 7045128 | J26: 0 | K26: 1774 | L26: 1774 | M26: housing_1 | N26: export.202502.categorized.csv
A27: TX-000054 | B27: 45738 | C27: 2025-03 | D27: Expense | E27: Freizeit | F27: Gastronomie | G27: Freizeit / Gastronomie | H27: +41790000000 MAX MUSTER | I27: MITTEILUNGEN: ESSEN GESTERN ABEND | J27: 0 | K27: 20 | L27: 20 | M27: gastronomy_5 | N27: export.202503.categorized.csv
A28: TX-000055 | B28: 45738 | C28: 2025-03 | E28: Uncategorized | G28: Uncategorized | H28: UNMATCHED TEST STORE | J28: 0 | K28: 12.4 | L28: 12.4 | M28: - | N28: export.202503.categorized.csv
A29: TX-000051 | B29: 45739 | C29: 2025-03 | D29: Expense | E29: Einkaufen | F29: Detail-Lebensmittel | G29: Einkaufen / Detail-Lebensmittel | H29: BÄCKEREI HUG | J29: 0 | K29: 17.3 | L29: 17.3 | M29: grocery_1 | N29: export.202503.categorized.csv
A30: TX-000052 | B30: 45739 | C30: 2025-03 | D30: Expense | E30: Wohnen | F30: Haushalt | G30: Wohnen / Haushalt | H30: MANOR AG - 771 (CENTRA) | J30: 0 | K30: 23.95 | L30: 23.95 | M30: home_2 | N30: export.202503.categorized.csv
A31: TX-000053 | B31: 45739 | C31: 2025-03 | D31: Expense | E31: Freizeit | F31: Gastronomie | G31: Freizeit / Gastronomie | H31: +41796666222 KEBAB, IMBISS | J31: 0 | K31: 13.5 | L31: 13.5 | M31: gastronomy_4 | N31: export.202503.categorized.csv
A32: TX-000045 | B32: 45740 | C32: 2025-03 | D32: Expense | E32: Einkaufen | F32: Detail-Lebensmittel | G32: Einkaufen / Detail-Lebensmittel | H32: WAKARA GMBH | J32: 0 | K32: 27.6 | L32: 27.6 | M32: grocery_2 | N32: export.202503.categorized.csv
A33: TX-000046 | B33: 45740 | C33: 2025-03 | D33: Expense | E33: Leben | F33: Styling und Wellness | G33: Leben / Styling und Wellness | H33: THE BODY SHOP | J33: 0 | K33: 4.95 | L33: 4.95 | M33: wellness_1 | N33: export.202503.categorized.csv
A34: TX-000047 | B34: 45740 | C34: 2025-03 | D34: Expense | E34: Einkaufen | F34: Supermärkte | G34: Einkaufen / Supermärkte | H34: COOP-5510 RIVERSIDE REST. | J34: 0 | K34: 44 | L34: 44 | M34: supermarket_1 | N34: export.202503.categorized.csv
A35: TX-000048.1 | B35: 45740 | C35: 2025-03 | D35: Expense | E35: Wohnen | F35: Haushalt | G35: Wohnen / Haushalt | H35: MIGROS MARKTHALLE (8812) | J35: 0 | K35: 18.9 | L35: 18.9 | M35: supermarket_1 | N35: export.202503.categorized.csv
A36: TX-000048.2 | B36: 45740 | C36: 2025-03 | D36: Expense | E36: Einkaufen | F36: Supermärkte | G36: Einkaufen / Supermärkte | H36: MIGROS MARKTHALLE (8812) | J36: 0 | K36: 34.6 | L36: 34.6 | M36: supermarket_1 | N36: export.202503.categorized.csv
A37: TX-000049 | B37: 45740 | C37: 2025-03 | D37: Expense | E37: Freizeit | F37: Gastronomie | G37: Freizeit / Gastronomie | H37: MIGROS CITY TAKE AWAY (6624) | J37: 0 | K37: 6.8 | L37: 6.8 | M37: gastronomy_1 | N37: export.202503.categorized.csv
A38: TX-000050 | B38: 45740 | C38: 2025-03 | D38: Expense | E38: Leben | F38: Krankenkasse | G38: Leben / Krankenkasse | H38: MEDICURA PLUS AG GESUNDHEITSWEG 8 4052 BASEL | J38: 0 | K38: 77.45 | L38: 77.45 | M38: health_2 | N38: export.202503.categorized.csv
A39: TX-000039 | B39: 45741 | C39: 2025-03 | D39: Expense | E39: Einkaufen | F39: Detail-Lebensmittel | G39: Einkaufen / Detail-Lebensmittel | H39: BÄCKEREI HUG | J39: 0 | K39: 6.1 | L39: 6.1 | M39: grocery_1 | N39: export.202503.categorized.csv
A40: TX-000040 | B40: 45741 | C40: 2025-03 | D40: Expense | E40: Einkaufen | F40: Detail-Lebensmittel | G40: Einkaufen / Detail-Lebensmittel | H40: BRANKOVIC BREZELSTUBE | J40: 0 | K40: 4.3 | L40: 4.3 | M40: grocery_1 | N40: export.202503.categorized.csv
...

Sheet Top Payees
A1: Category | B1: Subcategory | C1: Payee | D1: Net | E1: Count | F1: Months | G1: Share | H1: Rank
A2: Wohnen | B2: Miete und Hypothek | C2: FINANZVERWALTUNG STADT SOLOTHURN | D2: 7096 | E2: 4 | F2: 4 | G2: 1 | H2: 1
A3: Einkaufen | B3: Supermärkte | C3: MIGROS MARKTHALLE | D3: 804.7 | E3: 9 | F3: 4 | G3: 0.6189 | H3: 1
A4: Einkaufen | B4: Supermärkte | C4: COOP-5510 RIVERSIDE REST. | D4: 286.4 | E4: 4 | F4: 4 | G4: 0.2203 | H4: 2
A5: Einkaufen | B5: Supermärkte | C5: MIGROS M RIVERSIDE | D5: 201.4 | E5: 6 | F5: 4 | G5: 0.1549 | H5: 3
A6: Einkaufen | B6: Supermärkte | C6: COOP - 7811 QUAI WEST | D6: 7.75 | E6: 1 | F6: 1 | G6: 0.006 | H6: 4
A7: Leben | B7: Familie | C7: FAMILIENKASSE MUSTERHAUSEN | D7: 200 | E7: 1 | F7: 1 | G7: 0.9804 | H7: 1
A8: Leben | B8: Familie | C8: ZMITTAG 13.1. | D8: 19 | E8: 1 | F8: 1 | G8: 0.0931 | H8: 2
A9: Leben | B9: Familie | C9: MUSTER UND BEISPIEL GEMEINSCHAFTSKONTO MUSTERWEG 1 4600 OLTEN | D9: -15 | E9: 1 | F9: 1 | G9: -0.0735 | H9: 3
A10: Freizeit | B10: Gastronomie | C10: YOOJI'S ROSENGARTEN | D10: 62.3 | E10: 3 | F10: 1 | G10: 0.35 | H10: 1
A11: Freizeit | B11: Gastronomie | C11: +41796666222 KEBAB, IMBISS | D11: 27.5 | E11: 2 | F11: 1 | G11: 0.1545 | H11: 2
A12: Freizeit | B12: Gastronomie | C12: COOP-5510 RIVERSIDE REST. | D12: 24.5 | E12: 1 | F12: 1 | G12: 0.1376 | H12: 3
A13: Freizeit | B13: Gastronomie | C13: +41790000000 MAX MUSTER | D13: 20 | E13: 1 | F13: 1 | G13: 0.1124 | H13: 4
... A43: Finanzen | B43: Fees | C43: PREIS FÜR BANKPAKET SMART 02.2025 | D43: 5 | E43: 1 | F43: 1 | G43: 1 | H43: 1
A44: Rückerstattungen | C44: +41790000000 MAX MUSTER | D44: -1 | E44: 1 | F44: 1 | G44: 1 | H44: 1
A45: Uncategorized | C45: FIKTIVE DIGITAL GMBH | D45: 33.7 | E45: 1 | F45: 1 | G45: -3.2249 | H45: 1
A46: Uncategorized | C46: FIKTIVE POST AG | D46: 12.5 | E46: 1 | F46: 1 | G46: -1.1962 | H46: 2
A47: Uncategorized | C47: UNMATCHED TEST STORE | D47: 12.4 | E47: 1 | F47: 1 | G47: -1.1866 | H47: 3
A48: Uncategorized | C48: FIKTIVER FAHRSCHEIN BERLIN DEUTSCHLAND | D48: -19.15 | E48: 1 | F48: 1 | G48: 1.8325 | H48: 4
A49: Uncategorized | C49: FIKTIVER SCHUHLADEN BIEL | D49: -49.9 | E49: 1 | F49: 1 | G49: 4.7751 | H49: 5
A50: Mobilität | B50: Öffentlicher Verkehr | C50: TRANSPORTS PUBLICS FRIBOURGEOIS (FAIRTIQ) N/A PAYMENT ID 250326064915818975ZX BESTELLNUMMER | D50: 62.6 | E50: 1 | F50: 1 | G50: -0.6667 | H50: 1
A51: Mobilität | B51: Öffentlicher Verkehr | C51: TRANSPORTS PUBLICS FRIBOURGEOIS (FAIRTIQ) N/A PAYMENT ID 250328064754083058ZX BESTELLNUMMER | D51: 34.3 | E51: 1 | F51: 1 | G51: -0.3653 | H51: 2
A52: Mobilität | B52: Öffentlicher Verkehr | C52: ALPENWERK AG INDUSTRIESTRASSE 12 CH-5430 WETTINGEN AG | D52: -190.8 | E52: 3 | F52: 3 | G52: 2.0319 | H52: 3
A53: Freizeit | B53: Reisen und Erleben | C53: UEFA WOMEN'S EURO 2025 NYON | D53: -100 | E53: 1 | F53: 1 | G53: 0.3571 | H53: 1
A54: Freizeit | B54: Reisen und Erleben | C54: ALPENWERK AG INDUSTRIESTRASSE 12 CH-5430 WETTINGEN AG | D54: -180 | E54: 1 | F54: 1 | G54: 0.6429 | H54: 2
A55: Leben | B55: Krankenkasse | C55: MUSTER UND BEISPIEL GEMEINSCHAFTSKONTO MUSTERWEG 1 4600 OLTEN | D55: -120 | E55: 1 | F55: 1 | G55: 0.0656 | H55: 1
A56: Leben | B56: Krankenkasse | C56: MEDICURA PLUS AG GESUNDHEITSWEG 8 4052 BASEL | D56: -1710.5 | E56: 2 | F56: 1 | G56: 0.9344 | H56: 2
